Workbook

Sheet Sheet1
A1: TANGGAL | C1: 45945 | E1: SHIPMENT WEEK | G1: ASAP - AMEIDE
A2: NO PO | C2: 2025-10/PO/VDL-117SJ | E2: NO. ORDER CUST. | G2: 112682
B3: ART NO | D3: FIN | E3: QTY ORDER | F3: REST QTY | G3: FCL | H3: %
A4: 1 | B4: 306382 | C4: LOUNGE TABLE 120X65H35CM TEAKWOOD- FINISHING RUSTIC OUTDOOR | D4: FRO- FINISHING RUSTIC OUTDOOR | E4: 10 | F4: 5 | G4: 806 | H4: =F4/G4 -> 0.0062034739
A5: 2 | B5: 306383 | C5: RESTAURANT TABLE D70H74CM TEAKWOOD- FINISHING RUSTIC OUTDOOR | D5: FRO- FINISHING RUSTIC OUTDOOR | E5: 10 | F5: 5 | G5: 738 | H5: =F5/G5 -> 0.0067750678
A6: 4 | B6: 306384 | C6: DINING OUTDOOR TABLE 240X100H78CM TEAKWOOD- FINISHING RUSTIC OUTDOOR | D6: FRO- FINISHING RUSTIC OUTDOOR | E6: 10 | F6: 7 | G6: 164 | H6: =F6/G6 -> 0.042682927
A7: 5 | B7: 306385 | C7: DINING OUTDOOR TABLE 300X100H78CM TEAKWOOD- FINISHING RUSTIC OUTDOOR | D7: FRO- FINISHING RUSTIC OUTDOOR | E7: 10 | F7: 7 | G7: 102 | H7: =F7/G7 -> 0.068627451
B8: * | C8: SHIPMENT TO AMEIDE
B9: * | C9: STANDARD LABEL & PACKING
F10: =SUM(F4:F9) -> 24 | H10: =SUM(H4:H9) -> 0.12428892
A11: TANGGAL | C11: 46076 | E11: SHIPMENT WEEK | G11: ASAP - AMEIDE
A12: NO PO | C12: 2025-11/PO/VDL-141P / 028SJ | E12: NO. ORDER CUST. | G12: 112791
B13: ART NO | D13: FIN | E13: QTY ORDER | F13: REST QTY | G13: FCL | H13: %
C14: SHIPMENT: MAX WEEK 17
A15: 1 | B15: 304703 | C15: SLICE W/GRIP RECT 50X40H3.5CM- RUSTIC | D15: NATURAL | E15: 738 | F15: 738 | G15: 8211 | H15: =F15/G15 -> 0.08987943
B16: * | C16: SHIPMENT TO AMEIDE
B17: * | C17: WITH FOODSAFE STAMP
B18: * | C18: NO NEED 1XSHIPMENT
B19: * | C19: STANDARD LABEL & PACKING TYPE
F20: =SUM(F14:F19) -> 738 | H20: =SUM(H14:H19) -> 0.08987943
A21: TANGGAL | C21: 46108 | E21: SHIPMENT WEEK | G21: A S A P / MAX 6 WEEKS - 1XSHIPMENT
A22: NO PO | C22: 2026-03/PO/VDL-049D | E22: NO. ORDER CUST. | G22: 112989 REF 11436
B23: ART NO | D23: FIN | E23: QTY ORDER | F23: REST QTY | G23: FCL | H23: %
A24: 1 | B24: 306398 | C24: DRYPOT BOWL TINA D32H10CM- ANT GREY | D24: ANTGREY | E24: 120 | F24: 120 | G24: 6720 | H24: =F24/G24 -> 0.017857143
A25: 2 | B25: 306399 | C25: DRYPOT BOWL TINA D40H16CM- ANT GREY | D25: ANTGREY | E25: 80 | F25: 80 | G25: 3192 | H25: =F25/G25 -> 0.025062657
A26: 3 | B26: 306400 | C26: DRYPOT BOWL TINA D60H25CM- ANT GREY | D26: ANTGREY | E26: 25 | F26: 25 | G26: 880 | H26: =F26/G26 -> 0.028409091
A27: 4 | B27: 901325 | C27: DRYPOT ANTGREY D34H30CM | D27: ANTGREY | E27: 50 | F27: 50 | G27: 2205 | H27: =F27/G27 -> 0.022675737
A28: 5 | B28: 901326 | C28: DRYPOT ANTGREY D39H36CM | D28: ANTGREY | E28: 50 | F28: 50 | G28: 1800 | H28: =F28/G28 -> 0.027777778
A29: 6 | B29: 901328 | C29: DRYPOT ANT GREY D45H44CM | D29: ANTGREY | E29: 50 | F29: 50 | G29: 1170 | H29: =F29/G29 -> 0.042735043
A30: 7 | B30: 901329 | C30: DRYPOT ANT GREY D54H48CM | D30: ANTGREY | E30: 10 | F30: 10 | G30: 528 | H30: =F30/G30 -> 0.018939394
B31: * | C31: SHIPMENT TO AMEIDE - 1XSHIPMENT - VIA NGORO
B32: * | C32: STANDARD LABEL & PACKING
F33: =SUM(F24:F32) -> 385 | H33: =SUM(H24:H32) -> 0.18345684
A34: TANGGAL | C34: 46108 | E34: SHIPMENT WEEK | G34: A S A P / MAX 6 WEEKS - 1XSHIPMENT
A35: NO PO | C35: 2026-03/PO/VDL-049SJ | E35: NO. ORDER CUST. | G35: 112989 REF 11436
B36: ART NO | D36: FIN | E36: QTY ORDER | F36: REST QTY | G36: FCL | H36: %
A37: 1 | B37: 305381 | C37: FRAME ONLY - BANDA DINING CHAIR 58X56H80CM- TEAK/ PANDAN | D37: NATURAL | E37: 20 | F37: 20 | G37: 566 | H37: =F37/G37 -> 0.035335689
A38: 2 | B38: 306384 | C38: DINING OUTDOOR TABLE 240X100H78CM TEAKWOODFINISHING RUSTIC OUTDOOR | D38: FRO- FINISHING RUSTIC OUTDOOR | E38: 4 | F38: 4 | G38: 164 | H38: =F38/G38 -> 0.024390244
A39: 3 | B39: 306385 | C39: DINING OUTDOOR TABLE 300X100H78CM TEAKWOODFINISHING RUSTIC OUTDOOR | D39: FRO- FINISHING RUSTIC OUTDOOR | E39: 2 | F39: 2 | G39: 102 | H39: =F39/G39 -> 0.019607843
B40: * | C40: SHIPMENT TO AMEIDE - 1XSHIPMENT - VIA NGORO
...

Sheet Sheet2
A1: PO DATE | B1: PO NO | C1: SHIPMENT WEEK | D1: NO ORDER CUSTOMER | E1: ART NO | F1: DESKRIPSI | G1: FINISHING | H1: QTY ORDER | I1: REST QTY | J1: FCL | K1: %
A2: 45945 | B2: 2025-10/PO/VDL-117SJ | C2: ASAP | D2: 112682 | E2: 306382 | F2: LOUNGE TABLE 120X65H35CM TEAKWOOD- FINISHING RUSTIC OUTDOOR | G2: FRO- FINISHING RUSTIC OUTDOOR | H2: 10 | I2: 5 | J2: 806 | K2: 0.0062034739
A3: 45945 | B3: 2025-10/PO/VDL-117SJ | C3: ASAP | D3: 112682 | E3: 306383 | F3: RESTAURANT TABLE D70H74CM TEAKWOOD- FINISHING RUSTIC OUTDOOR | G3: FRO- FINISHING RUSTIC OUTDOOR | H3: 10 | I3: 5 | J3: 738 | K3: 0.0067750678
A4: 45945 | B4: 2025-10/PO/VDL-117SJ | C4: ASAP | D4: 112682 | E4: 306384 | F4: DINING OUTDOOR TABLE 240X100H78CM TEAKWOOD- FINISHING RUSTIC OUTDOOR | G4: FRO- FINISHING RUSTIC OUTDOOR | H4: 10 | I4: 7 | J4: 164 | K4: 0.042682927
A5: 45945 | B5: 2025-10/PO/VDL-117SJ | C5: ASAP | D5: 112682 | E5: 306385 | F5: DINING OUTDOOR TABLE 300X100H78CM TEAKWOOD- FINISHING RUSTIC OUTDOOR | G5: FRO- FINISHING RUSTIC OUTDOOR | H5: 10 | I5: 7 | J5: 102 | K5: 0.068627451
A6: 46076 | B6: 2025-11/PO/VDL-028SJ | C6: ASAP | D6: 112791 | E6: 304703 | F6: SLICE W/GRIP RECT 50X40H3.5CM- RUSTIC | G6: NATURAL | H6: 738 | I6: 738 | J6: 8211 | K6: 0.08987943
A7: 46108 | B7: 2026-03/PO/VDL-049 D/SJ/H2 | C7: ASAP | D7: 112989 REF 11436 | E7: 306398 | F7: DRYPOT BOWL TINA D32H10CM- ANT GREY | G7: ANTGREY | H7: 120 | I7: 120 | J7: 6720 | K7: 0.017857143
A8: 46108 | B8: 2026-03/PO/VDL-049 D/SJ/H2 | C8: ASAP | D8: 112989 REF 11436 | E8: 306399 | F8: DRYPOT BOWL TINA D40H16CM- ANT GREY | G8: ANTGREY | H8: 80 | I8: 80 | J8: 3192 | K8: 0.025062657
A9: 46108 | B9: 2026-03/PO/VDL-049 D/SJ/H2 | C9: ASAP | D9: 112989 REF 11436 | E9: 306400 | F9: DRYPOT BOWL TINA D60H25CM- ANT GREY | G9: ANTGREY | H9: 25 | I9: 25 | J9: 880 | K9: 0.028409091
A10: 46108 | B10: 2026-03/PO/VDL-049 D/SJ/H2 | C10: ASAP | D10: 112989 REF 11436 | E10: 901325 | F10: DRYPOT ANTGREY D34H30CM | G10: ANTGREY | H10: 50 | I10: 50 | J10: 2205 | K10: 0.022675737
A11: 46108 | B11: 2026-03/PO/VDL-049 D/SJ/H2 | C11: ASAP | D11: 112989 REF 11436 | E11: 901326 | F11: DRYPOT ANTGREY D39H36CM | G11: ANTGREY | H11: 50 | I11: 50 | J11: 1800 | K11: 0.027777778
A12: 46108 | B12: 2026-03/PO/VDL-049 D/SJ/H2 | C12: ASAP | D12: 112989 REF 11436 | E12: 901328 | F12: DRYPOT ANT GREY D45H44CM | G12: ANTGREY | H12: 50 | I12: 50 | J12: 1170 | K12: 0.042735043
A13: 46108 | B13: 2026-03/PO/VDL-049 D/SJ/H2 | C13: ASAP | D13: 112989 REF 11436 | E13: 901329 | F13: DRYPOT ANT GREY D54H48CM | G13: ANTGREY | H13: 10 | I13: 10 | J13: 528 | K13: 0.018939394
A14: 46108 | B14: 2026-03/PO/VDL-049 D/SJ/H2 | C14: ASAP | D14: 112989 REF 11436 | E14: 305381 | F14: FRAME ONLY - BANDA DINING CHAIR 58X56H80CM- TEAK/ PANDAN | G14: NATURAL | H14: 20 | I14: 20 | J14: 566 | K14: 0.035335689
A15: 46108 | B15: 2026-03/PO/VDL-049 D/SJ/H2 | C15: ASAP | D15: 112989 REF 11436 | E15: 306384 | F15: DINING OUTDOOR TABLE 240X100H78CM TEAKWOODFINISHING RUSTIC OUTDOOR | G15: FRO- FINISHING RUSTIC OUTDOOR | H15: 4 | I15: 4 | J15: 164 | K15: 0.024390244
A16: 46108 | B16: 2026-03/PO/VDL-049 D/SJ/H2 | C16: ASAP | D16: 112989 REF 11436 | E16: 306385 | F16: DINING OUTDOOR TABLE 300X100H78CM TEAKWOODFINISHING RUSTIC OUTDOOR | G16: FRO- FINISHING RUSTIC OUTDOOR | H16: 2 | I16: 2 | J16: 102 | K16: 0.019607843
A17: 46108 | B17: 2026-03/PO/VDL-049 D/SJ/H2 | C17: ASAP | D17: 112989 REF 11436 | E17: 305535 | F17: STACKING CHAIR 58X54H83CM TEAK- SYNTHETIC SEAGRASS | G17: NATURAL TEAK | H17: 12 | I17: 12 | J17: 642 | K17: 0.018691589
A18: 46112 | B18: 2026-03/PO/VDL-053P | C18: ASAP | D18: 119998 | E18: 304810 | F18: PLATE WITH LEGS D30H7CM- NAT/BLACK | G18: NATURAL-BLACK | H18: 1000 | I18: 1000 | J18: 9840 | K18: =I18/J18 -> 0.10162602
A19: 46119 | B19: 2026-04/PO/VDL-055P | C19: ASAP | D19: 113007 | E19: 300940 | F19: STOOL TEAK NATURAL D15H17CM | G19: NATURAL | H19: 2000 | I19: 500 | J19: 19236 | K19: =I19/J19 -> 0.02599293
A20: 46119 | B20: 2026-04/PO/VDL-055P | C20: ASAP | D20: 113007 | E20: 301110 | F20: PLATE WITH 4 LEGS TEAK NATURAL D15H5CM | G20: NATURAL | H20: 1500 | I20: 1500 | J20: 54360 | K20: =I20/J20 -> 0.027593819
A21: 46119 | B21: 2026-04/PO/VDL-055P | C21: ASAP | D21: 113007 | E21: 301111 | F21: PLATE WITH 4 LEGS TEAK NATURAL D20H6CM | G21: NATURAL | H21: 1500 | I21: 1500 | J21: 29808 | K21: =I21/J21 -> 0.050322061
A22: 46119 | B22: 2026-04/PO/VDL-055P | C22: ASAP | D22: 113007 | E22: 301112 | F22: PLATE WITH 4 LEGS TEAK NATURAL D30H7CM | G22: NATURAL | H22: 1500 | I22: 1500 | J22: 12432 | K22: =I22/J22 -> 0.12065637
A23: 46119 | B23: 2026-04/PO/VDL-055P | C23: ASAP | D23: 113007 | E23: 304900 | F23: LOW TABLE D20H5CM TEAKWOOD- NEW LEG | G23: NATURAL | H23: 1000 | I23: 1000 | J23: 41112 | K23: =I23/J23 -> 0.024323798
A24: 46119 | B24: 2026-04/PO/VDL-055P | C24: ASAP | D24: 113007 | E24: 301131 | F24: PLATE WITH 4 LEGS TEAK NATURAL D40H8CM | G24: NATURAL | H24: 500 | I24: 500 | J24: 6432 | K24: =I24/J24 -> 0.077736318
A25: 46119 | B25: 2026-04/PO/VDL-056SJ | C25: ASAP | D25: 113025 | E25: 306635 | F25: LANTERN WOODEN SLATS D20H10CM GLAS D7.5CM FINISHING RUSTIC OUTDOOR | G25: FROFINISHING RUSTIC OUTDOOR | H25: 1000 | I25: 789 | J25: 11448 | K25: 0.068920335
A26: 46119 | B26: 2026-04/PO/VDL-056SJ | C26: ASAP | D26: 113025 | E26: 306636 | F26: SQUARE WOODEN LANTERN 20X20H25CM GLAS D7.5CM FINISHING RUSTIC OUTDOOR | G26: FROFINISHING RUSTIC OUTDOOR | H26: 1000 | I26: 770 | J26: 4860 | K26: 0.15843621
A27: 46136 | B27: 2026-04/PO/VDL-069D | C27: ASAP | D27: 113048 | E27: 302935 | F27: DRYPOT JUMBO CL D130H72CM | G27: CL-NATURAL | H27: 10 | I27: 5 | J27: 45 | K27: 0.11111111
A28: 46136 | B28: 2026-04/PO/VDL-069D | C28: ASAP | D28: 113048 | E28: 306398 | F28: DRYPOT BOWL TINA D32H10CM- ANT GREY | G28: ANTGREY | H28: 1000 | I28: 592 | J28: 6720 | K28: 0.088095238
A29: 46136 | B29: 2026-04/PO/VDL-069D | C29: ASAP | D29: 113048 | E29: 306403 | F29: DRYPOT SQUARE TINA LOW 44X44H15CM- ANT GREY | G29: ANTGREY | H29: 500 | I29: 216 | J29: 2688 | K29: 0.080357143
A30: 46136 | B30: 2026-04/PO/VDL-069D | C30: ASAP | D30: 113048 | E30: 302606 | F30: DRYPOT NATURAL ABACA D27H20CM | G30: NATURAL | H30: 500 | I30: 78 | J30: 4704 | K30: 0.016581633
A31: 46147 | B31: 2026-05/PO/VDL-070 D/H2/SJ/P/S | C31: ASAP | D31: 113054 | E31: 306140 | F31: TROLLEY KUBUS 53X53H56CM W/WHEELS- ANT GREY | G31: ANTGREY | H31: 15 | I31: 15 | J31: 440 | K31: 0.034090909
A32: 46147 | B32: 2026-05/PO/VDL-070 D/H2/SJ/P/S | C32: ASAP | D32: 113054 | E32: 306398 | F32: DRYPOT BOWL TINA D32H10CM- ANT GREY | G32: ANTGREY | H32: 500 | I32: 500 | J32: 6720 | K32: 0.074404762
A33: 46147 | B33: 2026-05/PO/VDL-070 D/H2/SJ/P/S | C33: ASAP | D33: 113054 | E33: 306399 | F33: DRYPOT BOWL TINA D40H16CM- ANT GREY | G33: ANTGREY | H33: 500 | I33: 500 | J33: 3192 | K33: 0.1566416
A34: 46147 | B34: 2026-05/PO/VDL-070 D/H2/SJ/P/S | C34: ASAP | D34: 113054 | E34: 306400 | F34: DRYPOT BOWL TINA D60H25CM- ANT GREY | G34: ANTGREY | H34: 250 | I34: 250 | J34: 880 | K34: 0.28409091
A35: 46147 | B35: 2026-05/PO/VDL-070 D/H2/SJ/P/S | C35: ASAP | D35: 113054 | E35: 306403 | F35: DRYPOT SQUARE TINA LOW 44X44H15CM- ANT GREY | G35: ANTGREY | H35: 250 | I35: 250 | J35: 2688 | K35: 0.093005952
A36: 46147 | B36: 2026-05/PO/VDL-070 D/H2/SJ/P/S | C36: ASAP | D36: 113054 | E36: 306404 | F36: DRYPOT SQUARE TINA LOW 50X50H18CM- ANT GREY | G36: ANTGREY | H36: 250 | I36: 250 | J36: 1584 | K36: 0.15782828
... A69: 46176 | B69: 2026-06/PO/VDL-083 D/MI/F/H2/SJ/P | C69: ASAP | D69: 113106 | E69: 306536 | F69: CANDLE HOLDER RECT W/ 4 CANDLE HOLDERS 57X15H9-16CM- MAHOGANY WOOD | G69: VINTAGE LOOK | H69: 20 | I69: 20 | J69: 4160 | K69: 0.0048076923
A70: 46176 | B70: 2026-06/PO/VDL-083 D/MI/F/H2/SJ/P | C70: ASAP | D70: 113106 | E70: 304703 | F70: SLICE W/GRIP RECT 50X40H3.5CM- RUSTIC (SLICE FOR TIKIBAR) | G70: NATURAL | H70: 6 | I70: 6
A71: 46176 | B71: 2026-06/PO/VDL-083 D/MI/F/H2/SJ/P | C71: ASAP | D71: 113106 | E71: 300940 | F71: STOOL TEAK NATURAL D15H17CM | G71: NATURAL | H71: 2000 | I71: 2000 | J71: 19236 | K71: 0.10397172
A72: 46176 | B72: 2026-06/PO/VDL-083 D/MI/F/H2/SJ/P | C72: ASAP | D72: 113106 | E72: 301107 | F72: STOOL TEAK NATURAL D17H22CM | G72: NATURAL | H72: 1000 | I72: 1000 | J72: 11088 | K72: 0.09018759
...
